try {
    console.log(a + b);
} catch(err){
    console.log(err);
    console.log('there are is an err');
    console.log('the error was saved in error log');
}

console.log('my program does not stop');